Workbook

Sheet Total Materiales

Sheet Materiales y Materias Primas
A1: LISTADO GENERAL DE MATERIALES
A2: Obra:
A3: Ubicación:
A4: MATERIAL | E4: U/M | F4: Cantidad | G4: Importe | H4: Saldo
A5: Cemento gris P-250 | E5: S (50kg) | F5: =Muros!G40+Revestimientos!D24+Cubiertas!G16+Pisos!F32+'Baño 1er Nivel'!N32+'Baño 1er Nivel'!D20+'Tanque Agua'!D21 -> 25.9575 | G5: 7500 | H5: =F5*G5 -> 194681.25
A6: Cemento gris P-350 | E6: S(42,5kg) | F6: =Estructural!L29+H.Ciclopeo!E14 -> 48 | G6: 7500 | H6: =F6*G6 -> 360000
A7: Cemento Blanco | E7: S(1 kg) | F7: =Enchapes!L13+Enchapes!L16+Enchapes!L18+Enchapes!L19+Enchapes!L20+Enchapes!L23 -> 0.0634 | G7: 500 | H7: =F7*G7 -> 31.7
A8: Arena Lavada | E8: m3 | F8: =Muros!I40+Revestimientos!F24+Cubiertas!I16+Pisos!H32+Estructural!D35+H.Ciclopeo!E15 -> 5.0162564 | G8: 3000 | H8: =F8*G8 -> 15048.769
A9: Grava 19,1mm | E9: m3 | F9: =Estructural!L31+H.Ciclopeo!E16 -> 5 | G9: 3000 | H9: =F9*G9 -> 15000
A10: Grava 38,1mm | E10: m3 | F10: 0 | G10: 3000 | H10: =F10*G10 -> 0
A11: Rajón | E11: m3 | F11: =H.Ciclopeo!E13 -> 0 | G11: 3000 | H11: =F11*G11 -> 0
A12: Recebo | E12: m3 | F12: 0.918 | G12: 1500 | H12: =F12*G12 -> 1377
A13: Polvo de Piedra | E13: m3 | F13: 0.372 | G13: 4200 | H13: =F13*G13 -> 1562.4
A14: Hidrato de cal | E14: kg | F14: 0 | G14: 100 | H14: =F14*G14 -> 0
A15: Masilla de cal | E15: kg | F15: 0 | G15: 385 | H15: =F15*G15 -> 0
A16: Yeso de fraguado lento | E16: kg | F16: 0 | G16: 400 | H16: =F16*G16 -> 0
A17: Tierra caliza blanca | E17: m3 | F17: 0 | H17: =F17*G17 -> 0
A18: Acero Ø 10 mm | E18: kg | F18: 0 | H18: =F18*G18 -> 0
A19: Acero Ø 10 mm | E19: m | F19: 0 | G19: 200 | H19: =F19*G19 -> 0
A20: Acero Ø 12 mm | E20: kg | F20: 0 | H20: =F20*G20 -> 0
A21: Acero Ø 12 mm | E21: m | F21: 0 | G21: 260 | H21: =F21*G21 -> 0
A22: Acero Ø 16 mm | E22: kg | F22: 0 | H22: =F22*G22 -> 0
A23: Acero Ø 16 mm | E23: m | F23: 0 | G23: 280 | H23: =F23*G23 -> 0
A24: Alambre No 18 | E24: kg | F24: 0 | G24: 300 | H24: =F24*G24 -> 0
A25: Bloques 0,20m | E25: u | F25: 0 | G25: 120 | H25: =F25*G25 -> 0
A26: Bloques 0,15m | E26: u | F26: 0 | G26: 100 | H26: =F26*G26 -> 0
A27: Bloques 0,10m | E27: u | F27: 0 | G27: 100 | H27: =F27*G27 -> 0
A28: Ladrillos corrientes | E28: u | F28: 0 | G28: 30 | H28: =F28*G28 -> 0
A29: Piedra natural para muros | E29: m3 | F29: 0 | G29: 2000 | H29: =F29*G29 -> 0
A30: Celosías de hormigón | C30: (0,35mx0,35m) | E30: u | F30: 0 | G30: 250 | H30: =F30*G30 -> 0
C31: (0,25mx0,25m) | E31: u | F31: 0 | G31: 250 | H31: =F31*G31 -> 0
C32: (0,40mx0,20m) | E32: u | F32: 0 | G32: 250 | H32: =F32*G32 -> 0
A33: Celosías de Cerámica roja | C33: (0,20mx0,20m) | E33: u | F33: 0 | H33: =F33*G33 -> 0
C34: (0,18mx0,18m) | E34: u | F34: 0 | H34: =F34*G34 -> 0
C35: (0,13mx0,15m) | E35: u | F35: 0 | H35: =F35*G35 -> 0
C36: (0,08mx0,16mx0,1m) | E36: u | F36: 0 | H36: =F36*G36 -> 0
C37: (0,12mx0,25mx0,1m) | E37: u | F37: 0 | H37: =F37*G37 -> 0
A38: Losetas de barro para enchape (0,30mx0,30mx0,025m) | E38: u | F38: 0 | G38: 1350 | H38: =F38*G38 -> 0
C39: (0,15mx0,15mx0,025m) | E39: u | F39: 0 | G39: 1525 | H39: =F39*G39 -> 0
A40: Azulejos 0,15mx0,15m | E40: u | F40: 0 | H40: =F40*G40 -> 0
...

Sheet Hoja1

Sheet Mano de Obra
A1: ACTIVIDADES | B1: U/M | C1: Precio CUP | D1: Cantidad | E1: Costo CUP
A2: TRABAJOS VARIOS 001
A3: Terminación a Frota Gruesa | B3: M2 | C3: 90 | D3: 0 | E3: =PRODUCT(D3,C3) -> 0
A4: Colocación de Cartel Lumínico | B4: U | C4: 160 | D4: 0 | E4: =PRODUCT(D4,C4) -> 0
A5: Acarreo de Escombros | B5: M3 | C5: 750 | D5: 1 | E5: =PRODUCT(D5,C5) -> 750
A6: Acarreo de Tierra | B6: M3 | C6: 500 | D6: 0 | E6: =PRODUCT(D6,C6) -> 0
A7: Acarreo de Material Suelto a Vagón | B7: Vagón | C7: 20 | D7: 60 | E7: =PRODUCT(D7,C7) -> 1200
A8: Rehincho y Compactación Manual | B8: M2 | C8: 100 | D8: 14 | E8: =PRODUCT(D8,C8) -> 1400
A9: Ranurado en Pared | B9: M2 | C9: 40 | D9: 0 | E9: =PRODUCT(D9,C9) -> 0
A10: Chapea de Manigua | B10: M2 | C10: 30 | D10: 0 | E10: =PRODUCT(D10,C10) -> 0
A11: Colocación de Gigantografía | B11: U | C11: 100 | D11: 0 | E11: =PRODUCT(D11,C11) -> 0
A12: Colocación de Bancos Metálicos en Parques y Exteriores | B12: U | C12: 200 | D12: 0 | E12: =PRODUCT(D12,C12) -> 0
A13: Limpieza de Obra | B13: M2 | C13: 16 | D13: 100 | E13: =PRODUCT(D13,C13) -> 1600
A14: Demolición de Cerca de Mallas Perles | B14: M2 | C14: 270 | D14: 25 | E14: =PRODUCT(D14,C14) -> 6750
... A29: Arme y Desarme de Andamios | B29: m2 | C29: 50 | D29: 50 | E29: =PRODUCT(D29,C29) -> 2500
A30: Sub-total | E30: =SUM(E3:E29) -> 38080
A31: CARPINTERÍA 002
A32: Colocación de Ventana Sencilla | B32: U | C32: 392 | D32: 1 | E32: =PRODUCT(D32,C32) -> 392
A33: Colocación de Puertas con Marco | B33: U | C33: 400 | D33: 2 | E33: =PRODUCT(D33,C33) -> 800
A34: Colocación de Ventanas Doble | B34: U | C34: 500 | D34: 4 | E34: =PRODUCT(D34,C34) -> 2000
A35: Colocación de Carpintería de Aluminio | B35: M2 | C35: 540 | D35: 0 | E35: =PRODUCT(D35,C35) -> 0
A36: Colocación de Verjas de Platina | B36: M2 | C36: 300 | D36: 0 | E36: =PRODUCT(D36,C36) -> 0
A37: Demolición de Carpintería de Madera con Cristal | B37: M2 | C37: 300 | D37: 0 | E37: =PRODUCT(D37,C37) -> 0
A38: Desmonte de Ventanas | B38: U | C38: 60 | D38: 0 | E38: =PRODUCT(D38,C38) -> 0
A39: Desmonte de Puertas con Marcos | B39: U | C39: 100 | D39: 1 | E39: =PRODUCT(D39,C39) -> 100
A40: Elaboración de Verjas de Platina | B40: M2 | C40: 1200 | D40: 0 | E40: =PRODUCT(D40,C40) -> 0
A41: Elaboración de Marquetería para Cartel Lumínico | B41: U | C41: 500 | D41: 0 | E41: =PRODUCT(D41,C41) -> 0
A42: Colocación de llavines de Puertas | B42: U | C42: 240 | D42: 2 | E42: =PRODUCT(D42,C42) -> 480
A43: Colocación de Marcos Puertas | B43: U | C43: 160 | D43: 0 | E43: =PRODUCT(D43,C43) -> 0
... A85: Elaboración de Rejilla de Piso de Cabillas P/Registros hasta (0.40x0.40) m | B85: u | C85: 900 | D85: 0 | E85: =PRODUCT(D85,C85) -> 0
A86: Sub-total | E86: =SUM(E31:E85) -> 4132
A87: CUBIERTA 003
A88: Colocación de Cubierta Ligera | B88: M2 | C88: 200 | D88: 15 | E88: =PRODUCT(D88,C88) -> 3000
A89: Colocación de Tejas | B89: M2 | C89: 120 | D89: 0 | E89: =PRODUCT(D89,C89) -> 0
A90: Colocación de Purling | B90: Ml | C90: 50 | D90: 45 | E90: =PRODUCT(D90,C90) -> 2250
A91: Colocación de Falso Techo | B91: M2 | C91: 300 | D91: 0 | E91: =PRODUCT(D91,C91) -> 0
A92: Colocación de Cerchas Metálicas en Cubierta | B92: M2 | C92: 160 | D92: 0 | E92: =PRODUCT(D92,C92) -> 0
A93: Demolición de Cubierta Ligera | B93: M2 | C93: 180 | D93: 15 | E93: =PRODUCT(D93,C93) -> 2700
A94: Demolición de Falso Techo | B94: M2 | C94: 180 | D94: 0 | E94: =PRODUCT(D94,C94) -> 0
A95: Desmonte de Techo | B95: M2 | C95: 100 | D95: 15 | E95: =PRODUCT(D95,C95) -> 1500
...

Sheet Muros
B1: MUROS Y TABIQUES
C2: Area a | E2: Sub | G2: INDICES POR M2
B3: ACTIVIDAD | C3: cubrir | D3: u/m2 | E3: total | F3: cemento | G3: sub | H3: Arena | I3: sub | J3: Recebo | K3: sub | L3: Dosif.
C4: (m2) | E4: (u) | F4: (s) | G4: total | H4: (m3) | I4: total | J4: (m3) | K4: total
B5: Muros de bloques
B6: de Hormigón
B7: De 0.20 m de esp. | D7: 12.6 | E7: =C7*D7 -> 0 | F7: 0.1428 | G7: =C7*F7 -> 0 | H7: 0.0194 | I7: =C7*H7 -> 0 | J7: 0.0096 | K7: =C7*J7 -> 0 | L7: 1,4,2
B8: De 0.15m de esp. | D8: 12.6 | E8: =C8*D8 -> 0 | F8: 0.1071 | G8: =C8*F8 -> 0 | H8: 0.0146 | I8: =C8*H8 -> 0 | J8: 0.0074 | K8: =C8*J8 -> 0 | L8: 1,4,2
B9: De 0.10m de esp. | C9: 43 | D9: 12.6 | E9: =C9*D9 -> 541.8 | F9: 0.1274 | G9: =C9*F9 -> 5.4782 | H9: 0.0128 | I9: =C9*H9 -> 0.5504 | K9: =C9*J9 -> 0 | L9: 1.3
B10: Muros de ladrillos
B11: corrientes
B12: De 0.30 de esp. | D12: 105 | E12: =C12*D12 -> 0 | F12: 0.468 | G12: =C12*F12 -> 0 | H12: 0.079 | I12: =C12*H12 -> 0 | J12: 0.047 | K12: =C12*J12 -> 0 | L12: 1,5,3
B13: De 0.15m de esp. | D13: 53 | E13: =C13*D13 -> 0 | F13: 0.1845 | G13: =C13*F13 -> 0 | H13: 0.0251 | I13: =C13*H13 -> 0 | J13: 0.0127 | K13: =C13*J13 -> 0 | L13: 1,4,2
B14: De 0.10m de esp. | D14: 32 | E14: =C14*D14 -> 0 | F14: 0.1274 | G14: =C14*F14 -> 0 | H14: 0.0128 | I14: =C14*H14 -> 0 | K14: =C14*J14 -> 0
B15: total de ladrillos (u) | E15: =SUM(E12:E14) -> 0
B16: Muros de piedra
B17: natural | E17: (m3)
B18: Rústica de | D18: 0.6 | E18: =C18*D18 -> 0 | F18: 1.2744 | G18: =C18*F18 -> 0 | H18: 0.1284 | I18: =C18*H18 -> 0 | L18: 1.3
B19: 0.45 espesor
B20: Rústica de | D20: 0.4 | E20: =C20*D20 -> 0 | F20: 0.8496 | G20: =C20*F20 -> 0 | H20: 0.0856 | I20: =C20*H20 -> 0 | L20: 1.3
B21: 0.3 espesor
B22: total de piedras (m3) | E22: =SUM(E18,E20) -> 0
B23: Celosías de
B24: Hormigón
B25: De 0.35 x 0.35 | D25: 10 | E25: =C25*D25 -> 0 | F25: 0.0446 | G25: =C25*F25 -> 0 | H25: 0.0045 | I25: =C25*H25 -> 0 | L25: 1.3
B26: De 0.25 x 0.25 | D26: 18 | E26: =C26*D26 -> 0 | F26: 0.0807 | G26: =C26*F26 -> 0 | H26: 0.0081 | I26: =C26*H27 -> 0 | L26: 1.3
B27: De 0.4 x 0.20 | D27: 13 | E27: =C27*D27 -> 0 | F27: 0.0786 | G27: =C27*F27 -> 0 | H27: 0.0079 | I27: =C28*H27 -> 0 | L27: 1.3
B28: Celosías de
B29: ceramica roja
B30: De 0.20x0.20x0.10 | D30: 27 | E30: =C30*D30 -> 0 | F30: 0.1678 | G30: =C30*F30 -> 0 | H30: 0.169 | I30: =C30*H30 -> 0 | L30: 1.3
B31: cuadrada
B32: De 0.18x0.18x0.10 | D32: 32 | E32: =C32*D32 -> 0 | F32: 0.5735 | G32: =C32*F32 -> 0 | H32: 0.0058 | I32: =C32*H32 -> 0 | L32: 1.3
B33: octogonal
B34: De 0,13x0,15x0,1 | D34: 54 | E34: =C34*D34 -> 0 | F34: 0.435 | G34: =C34*F34 -> 0 | H34: 0.004 | I34: =C34*H34 -> 0 | L34: 1.3
B35: hexagonal
B36: De 0.08x0.16x0.10 | D36: 82 | E36: =C36*D36 -> 0 | F36: 0.035 | G36: =C36*F36 -> 0 | H36: 0.0035 | I36: =C36*H36 -> 0 | L36: 1.3
B37: semi-cilindro
B38: De 0.12x0.25x0.10 | D38: 35 | E38: =C38*D38 -> 0 | F38: 0.0425 | G38: =C38*F38 -> 0 | H38: 0.0043 | I38: =C38*H38 -> 0 | L38: 1.3
B39: ovalo
B40: total de la actividad -------- | G40: =SUM(G7:G39) -> 5.4782 | I40: =SUM(I7:I39) -> 0.5504 | K40: =SUM(K7:K14) -> 0

Sheet Revestimientos
A1: REVESTIMIENTOS,ENLUCIDOS Y ESTUCOS
B2: Area a | D2: INDICES POR M2
A3: ACTIVIDAD | B3: cubrir | C3: cemento | D3: sub. | E3: Arena | F3: sub. | G3: Recebo | H3: sub. | I3: Hidrato | J3: sub. | K3: Masilla | L3: sub. | M3: Yeso frag. | N3: sub. | O3: Dosif.
B4: (m2) | C4: (s) | D4: total | E4: (m3) | F4: total | G4: (m3) | H4: total | I4: Cal(kg) | J4: total | K4: cal( kg) | L4: total | M4: lento( kg) | N4: total
A5: SALPICADO
A6: Salpicado en pared y techo | B6: 121 | C6: 0.0072 | D6: =(B6*C6) -> 0.8712 | E6: 0.004 | F6: =B6*E6 -> 0.484 | O6: 1.3
A7: RESANO
A8: Resano en techo y alero | B8: 35 | C8: 0.0714 | D8: =(B8*C8) -> 2.499 | E8: 0.0096 | F8: =(B8*E8) -> 0.336 | I8: 0.672 | J8: =(B8*I8) -> 23.52 | O8: 1,4,10%
A9: Resano en paredes | B9: 86 | C9: 0.0893 | D9: =(B9*C9) -> 7.6798 | E9: 0.0122 | F9: =(B9*E9) -> 1.0492 | G9: 0.0062 | H9: =(B9*G9) -> 0.5332 | O9: 1,4,2
A10: REPELLO FINO | F10: (P.PIEDRA)
A11: Fino en techos y aleros | B11: 35 | C11: 0.0499 | D11: =(B11*C11) -> 1.7465 | E11: 0.0068 | F11: =(B11*E11) -> 0.238 | G11: 0.0035 | H11: =(B11*G11) -> 0.1225 | O11: 1,4,2
A12: Fino en paredes | B12: 86 | C12: 0.0458 | D12: =(B12*C12) -> 3.9388 | E12: 0.0062 | F12: =(B12*E12) -> 0.5332 | G12: 0.0032 | H12: =(B12*G12) -> 0.2752 | O12: 1,4,2
A13: total de la actividad-------------- | F13: =SUM(F11:F12) -> 0.7712
A14: RUSTICO
A15: Rustico en techos y aleros | C15: 0.2635 | D15: =(B15*C15) -> 0 | E15: 0.0268 | F15: =(B15*E15) -> 0 | I15: 1.0023 | J15: =(B15*I15) -> 0 | O15: 1,3,5
A16: Rustico en paredes | C16: 0.2319 | D16: =(B16*C16) -> 0 | E16: 0.0235 | F16: =(B16*E16) -> 0 | I16: 0.882 | J16: =(B16*I16) -> 0 | O16: 1,4,10%
A17: Enlucido en Paredes
A18: Con cemento blanco y | C18: 0.0457 | D18: =(B18*C18) -> 0 | K18: 7.488 | L18: =(B18*K18) -> 0 | O18: 4.1
A19: masilla de cal
A20: Con cemento gris y | C20: 0.0434 | D20: =(B20*C20) -> 0 | K20: 7.488 | L20: =(B20*K20) -> 0 | O20: 4.1
A21: masilla de cal
A22: Techo con masilla de cal y | K22: 7.488 | L22: =(B22*K22) -> 0 | M22: 1.633 | N22: =(B22*M22) -> 0 | O22: 4.1
A23: yeso
A24: total de la actividad-------------- | D24: =SUM(D6:D23) -> 16.7353 | F24: =SUM(F6:F9,F15:F16) -> 1.8692 | H24: =SUM(H9:H12) -> 0.9309 | J24: =SUM(J8:J16) -> 23.52 | L24: =SUM(L18:L22) -> 0 | N24: =SUM(N18:N22) -> 0

Sheet Enchapes
B1: ENCHAPES
C2: Area a | G2: INDICES POR M2
B3: ACTIVIDAD | C3: cubrir | D3: U/M2 | E3: sub. | F3: cemento | G3: sub. | H3: P.Piedra | I3: sub. | J3: Hidrato | K3: sub. | L3: cem/ | M3: sub.
C4: (m2) | E4: total | F4: (s) | G4: total | H4: (m3) | I4: total | J4: de Cal (kg) | K4: total | L4: juntas | M4: total
B5: Enchapes de
B6: ceramica roja
B7: Losetas de barro de | D7: 11.7 | E7: =(C7*D7) -> 0 | F7: 0.2108 | G7: =(C7*F7) -> 0 | H7: 0.0214 | I7: =(C7*H7) -> 0 | J7: 1.6 | K7: =(C7*J7) -> 0
B8: 0,30x0,30x0,025 m
B9: Losetas de barro de | D9: 47 | E9: =(C9*D9) -> 0 | F9: 0.2108 | G9: =(C9*F9) -> 0 | H9: 0.0214 | I9: =(C9*H9) -> 0 | J9: 1.6 | K9: =(C9*J9) -> 0
B10: 0,15x0,15x0,025 m
B11: Enchapes de ceramica
B12: blanca
B13: Azulejos de 0,15x0,15m | C13: 8 | D13: 47 | E13: =(C13*D13) -> 376 | F13: 0.2108 | G13: =(C13*F13) -> 1.6864 | H13: 0.0214 | I13: =(C13*H13) -> 0.1712 | J13: 1.6 | K13: =(C13*J13) -> 12.8 | L13: 0.02 | M13: =(C13*L13) -> 0.16
B14: Enchapes de piedras
B15: elaboradas
B16: Losas de marmol de | D16: 55 | E16: =(C16*D16) -> 0 | F16: 0.2108 | G16: =(C16*F16) -> 0 | H16: 0.0214 | I16: =(C16*H16) -> 0 | J16: 1.6 | K16: =(C16*J16) -> 0 | L16: 0.02 | M16: =(C16*L16) -> 0
B17: 0,20x0,10x0,02m
B18: Losetas de marmol de | D18: 5.9 | E18: =(C18*D18) -> 0 | F18: 0.4675 | G18: =(C18*F18) -> 0 | H18: 0.0156 | I18: =(C18*H18) -> 0 | L18: 0.02 | M18: =(C18*L18) -> 0
B19: 0,40x0,40x0,02
B20: Plancha de Mármol | D20: 1 | E20: =(C20*D20) -> 0 | F20: 0.07924 | G20: =(C20*F20) -> 0 | H20: 0.0026 | I20: =(C20*H20) -> 0 | L20: 0.0034 | M20: =(C20*L20) -> 0
B21: Enchapes de piedras
B22: sin elaborar | D22: (m3)
B23: De 0,05m de espesor | D23: 0.07 | E23: =(C23*D23) -> 0 | F23: 0.4216 | G23: =(C23*F23) -> 0 | H23: 0.0428 | I23: =(C23*H23) -> 0 | J23: 3.2 | K23: =(C23*J23) -> 0
B24: total de la actividad---------- | G24: =G7+G9+G13+G16+G18+G20+G23 -> 1.6864 | I24: =SUM(I7:I23) -> 0.1712 | K24: =SUM(K7:K23) -> 12.8 | M24: =SUM(M13:M19) -> 0.16

Sheet Cubiertas
B1: REVESTIMIENTOS DE CUBIERTAS
C2: Cantidad | G2: INDICES POR M2
B3: ACTIVIDAD | C3: a | D3: u/m2 | E3: sub. | F3: cemento | G3: sub. | H3: Arena | I3: sub. | J3: tierra | K3: sub. | L3: hidrato | M3: sub.
C4: Ejecutar | E4: total | F4: s | G4: total | H4: m3 | I4: total | J4: blanca(m3) | K4: total | L4: cal (m3) | M4: total
B5: TEJAS DE BARRO
B6: CRIOLLAS
B7: De 400 mm | D7: 24 | E7: =(C7*D7) -> 0 | F7: 0.17 | G7: =C7*F7 -> 0 | H7: 0.06 | I7: =C7*H7 -> 0
B8: FRANCESAS | D8: 14 | E8: =C8*D8 -> 0
B9: Soladura en Azotea | D9: 25 | E9: =C9*D9 -> 0 | F9: 0.13 | G9: =C9*F9 -> 0 | H9: 0.05 | I9: =C9*H9 -> 0 | L9: 0.009 | M9: =(C9*L9) -> 0
B10: Enrajonado en Azotea | F10: 0.14 | G10: =C10*F10 -> 0 | J10: 0.09 | K10: =C10*J10 -> 0 | L10: 0.01 | M10: =C10*L10 -> 0
B11: TEJAS DE ASBESTO
B12: CEMENTO
B13: Acanalada de 1830x1067 | D13: 0.714 | E13: =C13*D13 -> 0
B14: Tejas Galvanizadas | C14: 132 | D14: 0.37 | E14: =C14*D14 -> 48.84
B15: Canalón de 3.5m | D15: 0.32 | E15: =C15*D15 -> 0
B16: total de la actividad---------------------------------- | G16: =SUM(G7:G10) -> 0 | I16: =SUM(I7:I9) -> 0 | K16: =SUM(K10:K15) -> 0 | M16: =SUM(M9:M15) -> 0

Sheet Pisos
A3: COLOCACIÓN DE PISOS
B4: Cantidad | F4: INDICES POR M2
A5: ACTIVIDAD | B5: a | C5: U/M2 | D5: sub. | E5: cemento | F5: sub. | G5: Arena | H5: sub. | I5: Recebo | J5: sub. | K5: Hid. | L5: sub. | M5: cemento | N5: sub. | O5: Dosif.
B6: Ejecutar | D6: total | E6: s | F6: total | G6: m3 | H6: total | I6: m3 | J6: total | K6: Cal (kg) | L6: total | M6: p/juntas | N6: total
A7: PISOS DE LOSAS DE
A8: MARMOL
A9: De 0,20x0,20x0,02 | C9: 26.3 | D9: =B9*C9 -> 0 | E9: 0.255 | F9: =B9*E9 -> 0 | G9: 0.0342 | H9: =B9*G9 -> 0 | K9: 2.4 | L9: =B9*K9 -> 0 | M9: 0.02 | N9: =B9*M9 -> 0 | O9: 1,4,10%
A10: De 0,30x0,30x0,02 | C10: 11.7 | D10: =B10*C10 -> 0 | E10: 0.255 | F10: =B10*E10 -> 0 | G10: 0.0342 | H10: =B10*G10 -> 0 | K10: 2.4 | L10: =B10*K10 -> 0 | M10: 0.02 | N10: =B10*M10 -> 0 | O10: 1,4,10%
A11: De 0.40x0.40x0.02 | C11: 6.6 | D11: =B11*C11 -> 0 | E11: 0.255 | F11: =B11*E11 -> 0 | G11: 0.0342 | H11: =B11*G11 -> 0 | K11: 2.4 | L11: =B11*K11 -> 0 | M11: 0.02 | N11: =B11*M11 -> 0 | O11: 1,4,10%
A12: De Mortero
A13: De 0,30 de espesor | D13: =B13*C13 -> 0 | E13: 0.3611 | F13: =B13*E13 -> 0 | G13: 0.0364 | H13: =B13*G13 -> 0 | O13: 1.3
A14: De Losetas de Ceramica
A15: roja (barro)
A16: De 0,30x0,30x0,02 | C16: 12 | D16: =B16*C16 -> 0 | E16: 0.1404 | F16: =B16*E16 -> 0 | G16: 0.0237 | H16: =B16*G16 -> 0 | I16: 0.0141 | J16: =B16*I16 -> 0 | O16: 1,5,3
A17: De 0,20x0,20x0,02 | C17: 26 | D17: =B17*C17 -> 0 | E17: 0.1404 | F17: =B17*E17 -> 0 | G17: 0.0237 | H17: =B17*G17 -> 0 | I17: 0.0141 | J17: =B17*I17 -> 0 | O17: 1,5,3
A18: De losetas Hidraulicas
A19: (mosaicos)
A20: De 0,20x0,20x0,025 | C20: 26 | D20: =B20*C20 -> 0 | E20: 0.117 | F20: =B20*E20 -> 0 | G20: 0.0198 | H20: =B20*G20 -> 0 | I20: 0.0118 | J20: =B20*I20 -> 0 | M20: 0.01 | N20: =B20*M20 -> 0 | O20: 1,5,3
A21: De 0,25x0,25x0,025m | B21: 32 | C21: 17 | D21: =B21*C21 -> 544 | E21: 0.117 | F21: =B21*E21 -> 3.744 | G21: 0.0198 | H21: =B21*G21 -> 0.6336 | I21: 0.0118 | J21: =B21*I21 -> 0.3776 | M21: 0.01 | N21: =B21*M21 -> 0.32 | O21: 1,5,3
A22: De losetas de Terrazo
A23: (Baldosas)
A24: De 0,30x0,30x0,030 | C24: 12 | D24: =B24*C24 -> 0 | E24: 0.1544 | F24: =B24*E24 -> 0 | G24: 0.026 | H24: =B24*G24 -> 0 | I24: 0.0155 | J24: =B24*I24 -> 0 | M24: 0.01 | N24: =B24*M24 -> 0 | O24: 1,5,3
A25: De 0,40x0,40x0,030 | C25: 7 | D25: =B25*C25 -> 0 | E25: 0.1544 | F25: =B25*E25 -> 0 | G25: 0.026 | H25: =B25*G25 -> 0 | I25: 0.0155 | J25: =B25*I25 -> 0 | M25: 0.01 | N25: =B25*M25 -> 0 | O25: 1,5,3
A26: RODAPIES | C26: (U/ML)
A27: De losetas Hidraulicas | C27: 4.2 | D27: =B27*C27 -> 0 | E27: 0.0179 | F27: =B27*E27 -> 0 | G27: 0.0017 | H27: =B27*G27 -> 0 | K27: 0.136 | L27: =B27*K27 -> 0 | M27: 0.01 | N27: =B27*M27 -> 0 | O27: 1,3,10%
A28: de 0,25x0,08x0,016m
A29: De losetas de Terrazo
A30: (Baldosas)
A31: De 0,30x0,08x0,025m | C31: 3.5 | D31: =B31*C31 -> 0 | E31: 0.0179 | F31: =B31*E31 -> 0 | G31: 0.0017 | H31: =B31*G31 -> 0 | K31: 0.136 | L31: =B31*K31 -> 0 | M31: 0.01 | N31: =B31*M31 -> 0
A32: total de la actividad--------------------- | F32: =SUM(F9:F31) -> 3.744 | H32: =SUM(H9:H31) -> 0.6336 | J32: =SUM(J16:J31) -> 0.3776 | L32: =SUM(L9:L31) -> 0 | N32: =SUM(N9:N31) -> 0.32

Sheet Pinturas
B1: PINTURAS
C3: Cantidad | G3: INDICES POR M2
B4: ACTIVIDAD | C4: a | D4: Gl/m2 | E4: sub. | F4: L/M2 | G4: sub. | H4: Sacos/ | I4: sub. | J4: Alcohol | K4: sub.
C5: Ejecutar | E5: total | G5: total | H5: m2 | I5: total | J5: Gl/m2 | K5: total
B6: VINYL
B7: Pintura de vinyl s/repello fino | C7: 121 | D7: 0.05 | E7: =C7*D7 -> 6.05
B8: 2 manos
B9: Pintura de vinyl s/repello rústico | D9: 0.05 | E9: =C9*D9 -> 0
B10: 2 manos
B11: total pintura vinyl (gls) | E11: =SUM(E7:E9) -> 6.05
B12: LECHADA
B13: De cal sobre pared 2 manos | F13: 0.77 | G13: =C13*F13 -> 0
B14: Cementosa sobre pared 1 mano | H14: 0.022 | I14: =C14*H14 -> 0
B15: ACEITE
B16: Aparejo sobre auperficies de madera | D16: 0.03 | E16: =C16*D16 -> 0
B17: 1 mano
B18: Pintura de aceite sobre puertas y | D18: 0.05 | E18: =C18*D18 -> 0
B19: ventanas y superficies de madera
B20: 2 manos
B21: Pintura de aceite sobre pared 2 manos | D21: 0.05 | E21: =C21*D21 -> 0
B22: total pintura aceite (gls) | E22: =SUM(E16:E21) -> 0
B23: LACAS Y BARNICES
B24: Goma laca sobre superficies de | F24: 0.022 | G24: =C24*F24 -> 0 | J24: 0.024 | K24: =C24*J24 -> 0
B25: madera 1 mano
B26: Barniz sobre madera 1 mano | D26: 0.029 | E26: =C26*D26 -> 0
B27: PINTURAS ANTICORROSIVAS
B28: SOBRE METALES
B29: Minio, 1 mano | D29: 0.022 | E29: =C29*D29 -> 0
B30: Oxido rojo. 1 mano | D30: 0.03 | E30: =C30*D30 -> 0
B31: Rojo. 2 manos | D31: 0.06 | E31: =C31*D31 -> 0

Sheet Estructural
B1: Columnas | G1: Pedestal | K1: Vigas | Q1: Zapatas | U1: Plato
B2: Cantidad | C2: =D2 -> 5 | D2: 5 | E2: u | G2: Cantidad | I2: u | K2: Ancho (b) | L2: 0.2 | M2: m | Q2: Ancho (b) | S2: m | U2: Cantidad | W2: u
B3: Ancho (b) | C3: =D3 -> 0.2 | D3: 0.2 | E3: m | G3: Ancho (b) | H3: 0.35 | I3: m | K3: Peralto (h) | L3: 0.3 | M3: m | Q3: Peralto (h) | S3: m | U3: Ancho (b) | W3: m
B4: Peralto (h) | C4: =D4 -> 0.2 | D4: 0.2 | E4: m | G4: Peralto (h) | H4: 0.35 | I4: m | K4: Longitud (L) | L4: 28 | M4: m | Q4: Longitud (L) | S4: m | U4: Peralto (h) | W4: m
B5: Altura (L) | C5: =D5 -> 2.4 | D5: 2.4 | E5: m | G5: Altura (L) | H5: 0.8 | I5: m | K5: Área | L5: =L2*L3 -> 0.06 | M5: m² | Q5: Área | R5: =R2*R3 -> 0 | S5: m² | U5: Altura (L) | W5: m
B6: Área | C6: =D6 -> 0.04 | D6: =D3*D4 -> 0.04 | E6: m² | G6: Área | H6: =H3*H4 -> 0.1225 | I6: m² | K6: Volúmen | L6: =L4*L5 -> 1.68 | M6: m³ | Q6: Volúmen | R6: =R4*R5 -> 0 | S6: m³ | U6: Área | V6: =V3*V4 -> 0 | W6: m²
B7: Volúmen | C7: =D7 -> 0.096 | D7: =D5*D6 -> 0.096 | E7: m³ | G7: Volúmen | H7: =H5*H6 -> 0.098 | I7: m³ | K7: Longitud Cercos | L7: =((L2-0.06)*2)+((L3-0.06)*2) -> 0.76 | M7: m | Q7: Longitud Cercos | R7: =((R2-0.06)*2)+((R3-0.06)*2) -> -0.24 | S7: m | U7: Volúmen | V7: =V5*V6 -> 0 | W7: m³
B8: Volúmen Total | C8: =D8 -> 0.48 | D8: =D2*D7 -> 0.48 | E8: m³ | G8: Volúmen Total | H8: =H2*H7 -> 0 | I8: m³ | K8: Cantidad Cercos | L8: =L4/0.25 -> 112 | M8: u | Q8: Cantidad Cercos | R8: =R4/0.25 -> 0 | S8: u | U8: Volúmen Total | V8: =V2*V7 -> 0 | W8: m³
B9: Longitud Cercos | D9: =((D3-0.06)*2)+((D4-0.06)*2) -> 0.56 | E9: m | G9: Longitud Cercos | H9: =((H3-0.06)*2)+((H4-0.06)*2) -> 1.16 | I9: m | K9: Longitud Total Cercos | L9: =L7*L8 -> 85.12 | M9: m | Q9: Longitud Total Cercos | R9: =R7*R8 -> 0 | S9: m | U9: Longitud Aceros | V9: =(V3-0.1)+0.15 -> 0.05 | W9: m
B10: Cantidad Cercos | D10: =(D5/0.25)*D2 -> 48 | E10: u | G10: Cantidad Cercos | H10: =(H5/0.25)*H2 -> 0 | I10: u | K10: Longitud Aceros | L10: =L4+0.4+(L2*2)+0.4 -> 29.2 | M10: m | Q10: Longitud Aceros | R10: =R4+(R2*2) -> 0 | S10: m | U10: Cantidad Aceros | V10: 8 | W10: u
B11: Longitud Total Cercos | D11: =D9*D10 -> 26.88 | E11: m | G11: Longitud Total Cercos | H11: =H9*H10 -> 0 | I11: m | K11: Cantidad Aceros | L11: 4 | M11: u | Q11: Cantidad Aceros | R11: 4 | S11: u | U11: Longitud Total Aceros | V11: =V9*V10*V2 -> 0 | W11: m
B12: Longitud Aceros | D12: =D5+H4+0.4+0.1 -> 3.25 | E12: m | G12: Longitud Aceros | H12: =H5+R3+0.4+0.25+0.1 -> 1.55 | I12: m | K12: Longitud Total Aceros | L12: =L10*L11 -> 116.8 | M12: m | Q12: Longitud Total Aceros | R12: =R10*R11 -> 0 | S12: m | U12: Cemento | V12: =V7*1.03*8 -> 0 | W12: u
B13: Cantidad Aceros | D13: 4 | E13: u | G13: Cantidad Aceros | H13: 4 | I13: u | K13: Cemento | L13: =L6*1.03*8 -> 13.8432 | M13: u | Q13: Cemento | R13: =R6*1.03*7 -> 0 | S13: u | U13: Arena | V13: =V7*1.03*0.53 -> 0 | W13: m³
B14: Longitud Total Aceros | D14: =D12*D13*D2 -> 65 | E14: m | G14: Longitud Total Aceros | H14: =H12*H13*H2 -> 0 | I14: m | K14: Arena | L14: =L6*1.03*0.53 -> 0.917112 | M14: m³ | Q14: Arena | R14: =R6*1.03*0.47 -> 0 | S14: m³ | U14: Piedra | V14: =V7*1.03*0.74 -> 0 | W14: m³
B15: Cemento | C15: =C8*1.03*8 -> 3.9552 | D15: =D8*1.03*8 -> 3.9552 | E15: u | G15: Cemento | H15: =H8*1.03*8 -> 0 | I15: u | K15: Piedra | L15: =L6*1.03*0.74 -> 1.280496 | M15: m³ | Q15: Piedra | R15: =R6*1.03*0.83 -> 0 | S15: m³
B16: Arena | C16: =C8*1.03*0.53 -> 0.262032 | D16: =D8*1.03*0.53 -> 0.262032 | E16: m³ | G16: Arena | H16: =H8*1.03*0.53 -> 0 | I16: m³
B17: Piedra | C17: =C8*1.03*0.74 -> 0.365856 | D17: =D8*1.03*0.74 -> 0.365856 | E17: m³ | G17: Piedra | H17: =H8*1.03*0.74 -> 0 | I17: m³
B23: Losas
B24: Ancho (b) | C24: =D24 -> 2.9 | D24: 2.9 | E24: m | K24: TOTAL ACERO ½¨: | L24: =L12+R12 -> 116.8 | M24: m | N24: ó | O24: =L24/9 -> 12.977778 | P24: =ROUNDUP(O24,0) -> 13 | Q24: Barras de acero de 9m
B25: Largo(h) | C25: =D25 -> 12.4 | D25: 12.4 | E25: m | K25: TOTAL ACERO ⅝¨: | L25: =H14+V11+(L12*0.4)+D14 -> 111.72 | M25: m | N25: ó | O25: =L25/9 -> 12.413333 | P25: =ROUNDUP(O25,0) -> 13 | Q25: Barras de acero de 9m
B26: Altura (L) | C26: =D26 -> 0.1 | D26: 0.1 | E26: m | K26: TOTAL ACERO ⅜¨: | L26: =D33 -> 290.08 | M26: m | N26: ó | O26: =L26/9 -> 32.231111 | P26: =ROUNDUP(O26,0) -> 33 | Q26: Barras de acero de 9m
B27: Área | C27: =D27 -> 35.96 | D27: =D24*D25 -> 35.96 | E27: m² | K27: TOTAL Hormigón 21Mpa: | L27: =D8+H8+L6+V8+D28 -> 5.756 | M27: m³
B28: Volúmen | C28: =D28 -> 3.596 | D28: =D26*D27 -> 3.596 | E28: m³ | K28: TOTAL Hormigón 17Mpa: | L28: =R6 -> 0 | M28: m³
B29: Longitud Aceros Positivos | C29: =D29 -> 2.84 | D29: =D24-0.06 -> 2.84 | E29: m | K29: TOTAL Cemento | L29: =ROUNDUP(O29,0) -> 48 | M29: u | O29: =D15+H15+L13+R13+V12+D34 -> 47.42944
B30: Longitud Aceros Negativos | C30: =D30 -> 12.34 | D30: =D25-0.06 -> 12.34 | E30: m | K30: TOTAL Arena | L30: =ROUNDUP(O30,0) -> 4 | M30: m³ | O30: =D16+H16+L14+R14+V13+D35 -> 3.1422004
B31: Cantidad Aceros Positivos | C31: =C25/0.25 -> 49.6 | D31: =ROUNDUP(C31,0) -> 50 | E31: u | K31: TOTAL Piedra | L31: =ROUNDUP(O31,0) -> 5 | M31: m³ | O31: =D17+H17+L15+R15+V14+D36 -> 4.3872232
B32: Cantidad Aceros Negativos | C32: =C24/0.25 -> 11.6 | D32: =ROUNDUP(C32,0) -> 12 | E32: u
B33: Longitud Total Aceros | D33: =(D29*D31)+(D30*D32) -> 290.08 | E33: m
B34: Cemento | C34: =C28*1.03*8 -> 29.63104 | D34: =D28*1.03*8 -> 29.63104 | E34: u
B35: Arena | C35: =C28*1.03*0.53 -> 1.9630564 | D35: =D28*1.03*0.53 -> 1.9630564 | E35: m³
B36: Piedra | C36: =C28*1.03*0.74 -> 2.7408712 | D36: =D28*1.03*0.74 -> 2.7408712 | E36: m³

Sheet H.Ciclopeo
B3: Características de los materiales
B5: Cemento P-350 Fábrica José Mercerón
B6: Arena Lavada de Juragua
B7: Grava de 19,1mm Cantera de los Guaos
C9: Volúmen de | D9: Rajon | E9: 0.7 | F9: Indices por m3
B10: Tipo de Hormigón | C10: Hormigón | D10: 0.3 | E10: del vol. | F10: Cemento | G10: Subtotal | H10: Arena | I10: Subtotal | J10: Grava | K10: Subtotal
B11: ciclopeo (30% rajon) | C11: m3 | D11: (m3) | E11: total | F11: kg/m3 | G11: kg | H11: kg/m3 | I11: kg | J11: kg/m3 | K11: kg
B12: H-100 KG/CM2 | D12: =(C12*30)/100 -> 0 | E12: =(C12-D12) -> 0 | F12: 412 | G12: =E12*F12 -> 0 | H12: 765 | I12: =E12*H12 -> 0 | J12: 758 | K12: =E12*J12 -> 0
B13: TOTAL RAJON | C13: M3 | E13: =SUM(D12,0) -> 0
B14: TOTAL CEMENTO | C14: S (42,5 KG) | E14: =(G12/42.5) -> 0
B15: TOTAL ARENA | C15: M3 | E15: =(I12/1411) -> 0
B16: TOTAL GRAVA | C16: M3 | E16: =(K12/1259) -> 0

Sheet Encofrados
B2: MADERA PARA ENCOFRADOS Y PUNTILLAS
B4: PIEZAS | C4: m3 de Hormigón | D4: Indice consumo | E4: Sub total | F4: Indice madera | G4: Sub total | H4: Indice de | I4: Sub total
D5: tablas (pié/taller) | E5: (pié/taller) | F5: Auxiliar (pié/taller) | H5: puntillas (Kg)
B7: Tablas de madera | C7: =Estructural!L27+Estructural!L28+H.Ciclopeo!C12 -> 5.756 | D7: 200 | E7: =C7*D7 -> 1151.2
B9: Madera Auxiliar | C9: =C7 -> 5.756 | F9: 120 | G9: =C9*F9 -> 690.72
B11: Puntillas 2 1/2 calibre 12 | C11: =C7 -> 5.756 | H11: 0.023 | I11: =C11*H11 -> 0.132388

Sheet Electricidad
B3: INSTALACION ELECTRICA
B4: Actividad | C4: m2 del | D4: Indice
C5: local | D5: u/m2 | E5: sub total
B6: COLOCACION
B7: De tomacorriente | C7: 32 | D7: 0.33 | E7: =(C7*D7) -> 10.56
B8: De interruptores | C8: 32 | D8: 0.11 | E8: =(C8*D8) -> 3.52
B9: Bombillo LED E27 | C9: 16 | D9: 0.11 | E9: =(C9*D9) -> 1.76
B10: Luminaria LED T8 | C10: 32 | D10: 0.11 | E10: =(C10*D10) -> 3.52
B11: Tuberias | D11: (m/m2)
B12: Tub.( Empotrada o expuesta) de | C12: 32 | D12: 1.6 | E12: =(C12*D12) -> 51.2
B13: PVC de 1/2 "
B14: Cable por tuberia
B15: TW 14 | C15: 32 | D15: 0.9 | E15: =(C15*D15) -> 28.8
B16: TW 12 | C16: 32 | D16: 2 | E16: =(C16*D16) -> 64

Sheet Baño 1er Nivel
A1: Instalacion hidrosanitaria
A4: Baño en primer nivel.Dimensiones Ancho: 1,4m, Largo: 2,4m, Puntal: 2,4m (Bajo Losa)
A5: Actividad | B5: total de | C5: Materiales | D5: Subtotal
B6: baños | C6: necesarios
A7: Equipos Sanitarios
A8: Tasa Sanitaria (u) | C8: 1 | D8: =(B8*C8) -> 0
A9: Lavamanos (u) | C9: 1 | D9: =(B9*C9) -> 0
A10: Tanque con tapa (u) | C10: 1 | D10: =(B10*C10) -> 0
A11: Cemento blanco (s) de 42,5 kg | C11: 0.1 | D11: =(B11*C11) -> 0
A12: Ramal interno de la vivienda y ventilación
A13: Cemento p-250 (s) | C13: 1 | D13: =(B13*C13) -> 0
A14: Arena (m3) | C14: 0.1 | D14: =(B14*C14) -> 0
A15: Tubo de PVC de 4" (m) | C15: 3 | D15: =(B15*C15) -> 0
A16: Instalación Hidráulica Plástica
A17: Tubo de 1" (m) | C17: 3 | D17: =(B17*C17) -> 0
A18: Tubo de 3/4" (m) | C18: 1.5 | D18: =(B18*C18) -> 0
A19: Tubo de 1/2" (m) | C19: 5.5 | D19: =(B19*C19) -> 0
A20: total cemento p-250 (s) 50 kg | D20: =D13 -> 0
A21: total arena (m3) | D21: =D14 -> 0

Sheet Baño 2do Nivel
A1: Instalacion hidrosanitaria
A3: Baño en segundo nivel.Dimensiones Ancho: 1,4m, Largo: 2,4m, Puntal: 2,4m (Bajo Losa)
A5: Actividad | B5: total de | C5: Materiales | D5: Subtotal
B6: baños | C6: necesarios
A7: Tuberías internas PVC
A8: De 4" (m) | C8: 10.5 | D8: =(B8*C8) -> 0
A9: De 2" (m) | C9: 3 | D9: =(B9*C9) -> 0
A10: Equipos Sanitarios
A11: Tasa Sanitaria (u) | C11: 1 | D11: =(B11*C11) -> 0
A12: Lavamanos (u) | C12: 1 | D12: =(B12*C12) -> 0
A13: Tanque con tapa (u) | C13: 1 | D13: =(B13*C13) -> 0
A14: Cemento blanco (s) de 42,5 kg | C14: 0.1 | D14: =(B14*C14) -> 0
A15: Instalación Hidráulica (HoGo)
A16: Tubo de 1" (m) | C16: 3 | D16: =(B16*C16) -> 0
A17: Tubo de 3/4" (m) | C17: 1.5 | D17: =(B17*C17) -> 0
A18: Tubo de 1/2" (m) | C18: 5.5 | D18: =(B18*C18) -> 0

Sheet Cocina 1er Nivel
A1: Instalacion hidrosanitaria
A2: Cocina en primer nivel.Dimensiones de la Meseta; ancho, 0,60m x 1,8 m de largo
A3: Actividad | B3: total de | C3: Materiales | D3: Subtotal
B4: cocinas | C4: necesarios
A5: Tuberías internas BoVo 4"
A6: De 4" (u) | B6: 1 | C6: 2 | D6: =(B6*C6) -> 2
A7: Cemento p-250 (s) | B7: 1 | C7: 0.12 | D7: =(B7*C7) -> 0.12
A8: Arena (m3) | B8: 1 | C8: 0.012 | D8: =(B8*C8) -> 0.012
A9: Equipos Sanitarios
A10: Fregadero (u) | B10: 1 | C10: 1 | D10: =(B10*C10) -> 1
A11: Cemento blanco (s) de 42,5 kg | B11: 1 | C11: 0.033 | D11: =(B11*C11) -> 0.033
A12: Ramal interno y ventilación
A13: Tubo de BoVo de 4" (u) | B13: 1 | C13: 5 | D13: =(B13*C13) -> 5
A14: Cemento p-250 (s) | B14: 1 | C14: 0.3 | D14: =(B14*C14) -> 0.3
A15: Arena (m3) | B15: 1 | C15: 0.03 | D15: =(B15*C15) -> 0.03
A16: Tubo de PVC de 4" (m) | B16: 1 | C16: 3 | D16: =(B16*C16) -> 3
A17: Instalación Hidráulica (HoGo)
A18: Tubo de 1" (m) | B18: 1 | C18: 2.8 | D18: =(B18*C18) -> 2.8
A19: Tubo de 3/4" (m) | B19: 1 | C19: 1 | D19: =(B19*C19) -> 1
A21: total cemento p-250 (s) 50 kg | D21: =SUM(D7,D14) -> 0.42
A22: total arena | D22: =SUM(D8,D15) -> 0.042

Sheet Tanque Agua
A1: VOLUMEN DE ALMACENAMIENTO DE AGUA
A3: TOTAL DE TANQUES DE ASBESTO DE 500 GLS A USAR.
A5: No de personas | B5: Indice de consumo | C5: Total de | D5: Ciclo de | E5: Volumen total | F5: Total de tanques
B6: de agua diario/personas | C6: litros diarios | D6: abasto de | E6: de agua a | F6: de asbesto cemento
B7: (lts/dia) | D7: agua (dias) | E7: almacenar (lts) | F7: de 500gls (1900 lts) a usar
A9: 3 | B9: 145 | C9: =(A9*B9) -> 435 | D9: 5 | E9: =(C9*D9) -> 2175 | F9: =(E9/1900) -> 1.1447368

Sheet Cocina 2do Nivel
A1: Instalacion hidrosanitaria
A3: Cocina en segundo nivel.Dimensiones de la Meseta; ancho, 0,60m x 1,8 m de largo
A5: Actividad | B5: total de | C5: Materiales | D5: Subtotal
B6: coc. | C6: necesarios
A7: Tuberías internas PVC
A8: De 4" (m) | C8: 4 | D8: =(B8*C8) -> 0
A9: Equipos Sanitarios
A10: Fregadero | C10: 1 | D10: =(B10*C10) -> 0
A11: Cemento blanco (s) de 42,5 kg | C11: 0.033 | D11: =(B11*C11) -> 0
A12: Instalación Hidráulica (HoGo)
A13: Tubo de 1" (m) | C13: 2.8 | D13: =(B13*C13) -> 0
A14: Tubo de 3/4" (m) | C14: 1 | D14: =(B14*C14) -> 0
